Workbook

Sheet 0-Leyenda
A1: PROTEGEME – Guia de Uso del Modelo de Costos y Precios
A2: ITFusion | Version 3 | Marzo 2026 | Uso interno y comercial
A4: 1. PARA QUE SIRVE ESTE ARCHIVO
A5: Este modelo tiene tres usos principales:
A6: 1 | B6: DEFINIR PRECIOS: Calcular el margen real de cada modulo al precio que cobra hoy, y simular que pasa si sube o baja el precio o si crece el numero de clientes. | C6: Hojas 2, 3, 4, 5, 6
A7: 2 | B7: COTIZAR CLIENTES: Generar una propuesta comercial completa seleccionando modulos, cantidades, plan de alcoholemia y descuento por paquete. | C7: Hoja 10-Cotizador
A8: 3 | B8: CONTROLAR COSTOS: Ver en tiempo real cuanto cuesta operar Protegeme por vehiculo y conductor, y como ese costo baja al crecer la base de clientes (apalancamiento SaaS). | C8: Hoja 1-Costos-Operativos
A10: 2. CONVENCIONES DE COLOR (regla de oro: solo edite las celdas AZULES)
A11: A | B11: Texto AZUL sobre fondo AMARILLO → Dato de entrada. Usted lo edita. | C11: Ej: precio de venta, numero de vehiculos, salarios
A12: B | B12: Texto NEGRO → Formula calculada automaticamente. No editar. | C12: Ej: margen real, costo total, utilidad por vehiculo
A13: C | B13: Texto VERDE → Dato vinculado desde otra hoja. | C13: Ej: costo por vehiculo traido desde Costos-Operativos
A14: D | B14: Fondo AZUL CLARO → Subtotal o total de seccion. | C14: No editar directamente
A15: E | B15: Fondo VERDE → Precio de venta sugerido o resultado clave. | C15: Precio final calculado con el margen objetivo
A16: F | B16: Fondo ROJO → Modulo futuro / no disponible aun. | C16: PESV Fase 2: integracion tiempo real con Supertransporte
A18: 3. ORDEN DE USO RECOMENDADO (primera vez)
A19: PASO 1 · Hoja 1-Costos-Operativos
A20: Ingrese sus costos reales: salarios del equipo (columna B de cada cargo), numero de personas (columna D), costos de plataformas (seccion D) y el numero de vehiculos y conductores activos hoy (celdas B6 y B7). Todo el modelo se alimenta desde esta hoja.
A21: PASO 2 · Hojas 2-SICOV y 3-App-Conductor
A22: Verifique el costo por vehiculo/conductor calculado (celda verde, seccion C). Luego en seccion D ingrese el precio minimo y maximo que cobra hoy (celdas amarillas). El modelo muestra el margen real que esta obteniendo y la tabla de descuentos por volumen.
A23: PASO 3 · Hojas 4 y 5 - Alcoholemia
A24: En hoja 4 revise el costo por soplada (seccion A) y el precio actual (fila amarilla). En hoja 5 ajuste los precios mensuales por tamano de empresa (fila amarilla). En hoja 9 configure los 3 planes de precios (seccion B, celdas azules) y revise la tabla de 4 rangos.
A25: PASO 4 · Hoja 6-PESV
A26: Ajuste los precios propuestos Fase 1 por categoria (fila amarilla, seccion C). El modelo calcula el margen y el precio sugerido al 70%. Fase 2 permanece en rojo hasta que este disponible la API de Supertransporte.
A27: PASO 5 · Hoja 7-Paquetes
A28: Verifique los precios base en seccion A (celdas amarillas). Ajuste los descuentos por paquete en columna D segun su estrategia comercial. La simulacion usa 20 vehiculos y 20 conductores por defecto: cambielos en seccion A.
A29: PASO 6 · Hoja 10-Cotizador
... A58: 6. ESTRUCTURA DE LAS 11 HOJAS
A59: Hoja | B59: Color pestaña | C59: Para que sirve
A60: 0-Leyenda | B60: Azul oscuro | C60: Esta guia de uso completa
A61: 1-Costos-Operativos | B61: Gris | C61: Fuente de verdad: personal + cloud + admin. Todo parte de aqui.
A62: 2-SICOV | B62: Verde | C62: Precio/vehiculo/mes. Margen real al precio que cobra hoy.
A63: 3-App-Conductor | B63: Morado | C63: Precio/conductor/mes. GPS + habitos + seguridad vial.
A64: 4-Alcoholemia-Soplada | B64: Azul | C64: Costo y precio por soplada individual. Dispositivo fisico.
A65: 5-Alcoholemia-Mensual | B65: Azul medio | C65: Precio base mensual por tamano de empresa.
A66: 6-PESV | B66: Rojo | C66: Fases 1 y 2. Clasificacion Supertransporte.
A67: 7-Paquetes | B67: Naranja | C67: Precios combinados con descuentos por paquete.
A68: 8-Resumen | B68: Azul petroleo | C68: Vista ejecutiva para inversionistas y equipo directivo.
A69: 9-Alc-Planes-Volumen | B69: Verde agua | C69: 3 planes alcoholemia (PPU / Fijo / Prepago). Tabla 4 rangos de consumo.
A70: 10-Cotizador | B70: Naranja dorado | C70: Cotizador interactivo por cliente. Exportable como propuesta comercial.
A72: Protegeme · ITFusion · Modelo de precios v3 · Marzo 2026 · Confidencial - uso interno

Sheet 1-Costos-Operativos
A1: COSTOS OPERATIVOS MENSUALES – Base para prorrateo de todos los módulos
A2: ℹ️ Esta hoja es la FUENTE DE VERDAD. Ingrese aquí sus costos reales. Los demás módulos toman el costo proporcional por vehículo/conductor desde aquí.
A4: A. PARÁMETROS DE FLOTA ACTIVA (para prorrateo)
A5: Parámetro | B5: Valor actual | C5: Proyección 6 meses | F5: Nota
A6: Vehículos activos (SICOV) | B6: 50 | C6: 120 | F6: Total vehículos facturando hoy
A7: Conductores activos (App Conductor) | B7: 50 | C7: 120 | F7: Total conductores facturando hoy
A8: Empresas con Alcoholemia mensual | B8: 5 | C8: 15 | F8: Empresas en base mensual alcoholemia
A9: Empresas con PESV contratado | B9: 3 | C9: 10 | F9: Clientes PESV activos
A11: B. PERSONAL – SOPORTE TÉCNICO
A12: Cargo | B12: Salario base (COP) | C12: Prestaciones (52%) | D12: # Personas | E12: Costo total/mes | F12: Nota
A13: Líder técnico / DevOps | B13: 4500000 | C13: =B13*0.52 -> 2340000 | D13: 1 | E13: =(B13+C13)*D13 -> 6840000 | F13: Infraestructura y despliegues
A14: Desarrollador backend (NestJS) | B14: 4000000 | C14: =B14*0.52 -> 2080000 | D14: 1 | E14: =(B14+C14)*D14 -> 6080000 | F14: APIs y lógica de negocio
A15: Desarrollador mobile (Flutter) | B15: 3800000 | C15: =B15*0.52 -> 1976000 | D15: 1 | E15: =(B15+C15)*D15 -> 5776000 | F15: App conductor + SICOV móvil
A16: Soporte N1 / helpdesk | B16: 2000000 | C16: =B16*0.52 -> 1040000 | D16: 1 | E16: =(B16+C16)*D16 -> 3040000 | F16: Atención incidencias clientes
A17: QA / Analista de datos | B17: 2800000 | C17: =B17*0.52 -> 1456000 | D17: 1 | E17: =(B17+C17)*D17 -> 4256000 | F17: Calidad y reportes
A18: SUBTOTAL SOPORTE TÉCNICO | E18: =SUM(E13:E17) -> 25992000
A20: C. PERSONAL – COMERCIAL Y SERVICIO AL CLIENTE
A21: Cargo | B21: Salario base (COP) | C21: Prestaciones (52%) | D21: # Personas | E21: Costo total/mes | F21: Nota
A22: Ejecutiva comercial (Madeleine A.) | B22: 3500000 | C22: =B22*0.52 -> 1820000 | D22: 1 | E22: =(B22+C22)*D22 -> 5320000 | F22: Ventas + comisiones aparte
A23: Asesor servicio al cliente | B23: 2200000 | C23: =B23*0.52 -> 1144000 | D23: 1 | E23: =(B23+C23)*D23 -> 3344000 | F23: Soporte funcional clientes
A24: Consultor onboarding / implementac. | B24: 2800000 | C24: =B24*0.52 -> 1456000 | D24: 1 | E24: =(B24+C24)*D24 -> 4256000 | F24: Implementación nuevos clientes
A25: SUBTOTAL COMERCIAL / SERVICIO AL CLIENTE | E25: =SUM(E22:E24) -> 12920000
A27: D. PLATAFORMAS, CLOUD Y SERVICIOS TECH
A28: Servicio | B28: Costo/mes (COP) | C28: ¿Escala con clientes? | F28: Proveedor
A29: Servidor VPS / Cloud (SSD Nodes / OCI) | B29: 300000 | C29: Sí
A30: Firebase (Firestore + Storage + Auth) | B30: 250000 | C30: Sí
A31: Google Maps API (GPS + rutas) | B31: 180000 | C31: Sí
A32: IA Visión (facial + alcoholemia) | B32: 200000 | C32: Sí
A33: CDN + WAF (Cloudflare) | B33: 80000 | C33: No
A34: MongoDB Atlas | B34: 150000 | C34: Sí
A35: Google Workspace (correo + docs) | B35: 60000 | C35: No
A36: CRM + soporte (HubSpot / Freshdesk) | B36: 80000 | C36: No
A37: Certificados SSL / Dominio | B37: 15000 | C37: No
A38: Backup y disaster recovery | B38: 50000 | C38: No
A39: Pasarela de pagos (comisiones est.) | B39: 100000 | C39: Sí
A40: Otros servicios tech | B40: 50000 | C40: No
A41: SUBTOTAL PLATAFORMAS / CLOUD | B41: =SUM(B29:B40) -> 1515000
A43: E. GASTOS GENERALES Y ADMINISTRATIVOS
A44: Concepto | B44: Costo/mes (COP) | F44: Nota
A45: Arriendo oficina / coworking | B45: 400000
...

Sheet 2-SICOV
A1: MÓDULO SICOV – Alistamiento y Mantenimiento de Vehículos
A2: ℹ️ El costo por vehículo/mes se compone de: (1) costos variables técnicos + (2) prorrateo del costo operativo desde hoja 1. El modelo calcula el margen REAL al precio que cobra hoy.
A4: A. COSTOS TÉCNICOS VARIABLES POR VEHÍCULO / MES
A5: Concepto | B5: Valor input | C5: Frecuencia/mes | D5: Costo parcial (COP) | G5: Nota
A6: Costo por foto (storage cloud) | B6: 30 | C6: COP/foto
A7: Fotos por registro de mantenimiento | B7: 5 | C7: fotos/registro
A8: Registros estimados / vehículo / mes | B8: 3 | C8: registros/mes
A9: → Costo almacenamiento / veh / mes | B9: =B6*B7*B8 -> 450 | C9: Calculado | D9: ↑ calculado
A10: Procesamiento IA por registro (visión) | B10: 80 | C10: COP/registro
A11: → Costo IA / veh / mes | B11: =B10*B8 -> 240 | C11: Calculado | D11: ↑ calculado
A12: Firmas digitales por registro | B12: 20 | C12: COP/firma
A13: → Costo firmas / veh / mes | B13: =B12*B8 -> 60 | C13: Calculado | D13: ↑ calculado
A14: Notificaciones push / SMS por veh/mes | B14: 200 | C14: COP/mes
A15: Subtotal costos técnicos variables / veh / mes | B15: =B9+B11+B13+B14 -> 950
A17: B. PRORRATEO DE COSTOS OPERATIVOS (desde hoja 1-Costos-Operativos)
A18: 📌 Este bloque toma el costo operativo total (personal+tech+admin) y lo divide entre los vehículos activos. A más clientes → menor costo/vehículo → mayor margen.
A19: Concepto | B19: Valor (COP) | C19: Fuente
A20: Total costos operativos / mes | B20: ='1-Costos-Operativos'!B55 -> 42054500 | C20: ← Hoja 1-Costos-Operativos
A21: Vehículos activos (SICOV) | B21: ='1-Costos-Operativos'!B6 -> 50 | C21: ← Hoja 1-Costos-Operativos
A22: PRORRATEO COSTO OPERATIVO / VEHÍCULO / MES | B22: ='1-Costos-Operativos'!B56 -> 841090 | C22: ← Se actualiza automáticamente
A24: C. COSTO TOTAL POR VEHÍCULO / MES
A25: Costos técnicos variables / veh / mes | B25: =B15 -> 950
A26: Prorrateo costos operativos / veh / mes | B26: ='1-Costos-Operativos'!B56 -> 841090
A27: COSTO TOTAL / VEHÍCULO / MES | B27: =B25+B26 -> 842040
A29: D. PRECIO DE MERCADO ACTUAL → MARGEN REAL
A30: 📌 Ingrese el precio que cobra hoy. El modelo calcula qué margen real está obteniendo. ESTO ES LO QUE IMPORTA.
A31: Parámetro | B31: Valor | G31: Interpretación
A32: Precio mínimo cobrado hoy (COP/veh/mes) | B32: 14000 | G32: Clientes con descuento / flota grande
A33: Precio estándar / máximo (COP/veh/mes) | B33: 18000 | G33: Precio de lista / clientes nuevos
A34: Costo total / vehículo / mes | B34: ='2-SICOV'!B27 -> 842040
A35: MARGEN REAL al precio mínimo (14K) | B35: =IF(B32>0,(B32-B34)/B32,0) -> -59.145714 | G35: Margen bruto real hoy — precio mínimo
A36: MARGEN REAL al precio estándar (18K) | B36: =IF(B33>0,(B33-B34)/B33,0) -> -45.78 | G36: Margen bruto real hoy — precio estándar
A37: Utilidad / vehículo / mes al precio estándar | B37: =B33-B34 -> -824040
A39: E. SIMULACIÓN DE PRECIO Y MARGEN POR VOLUMEN DE FLOTA
A40: 📌 El descuento se aplica sobre el precio estándar (celda D arriba). El margen se calcula contra el costo real. Si el margen cae bajo 60%, ajuste el descuento.
A41: Rango de Flota | B41: Descuento (%) | C41: Precio / veh / mes | D41: Costo / veh / mes | E41: Margen bruto (%) | F41: Utilidad / veh | G41: ¿Viable? (>60%)
A42: 1 – 10 vehículos | B42: 0 | C42: =ROUND(B33*(1-B42)/500,0)*500 -> 18000 | D42: ='2-SICOV'!B27 -> 842040 | E42: =IF(C42>0,(C42-D42)/C42,0) -> -45.78 | F42: =C42-D42 -> -824040 | G42: =IF(E42>=0.6,"✅ Sí","⚠️ Revisar") -> ⚠️ Revisar
A43: 11 – 30 vehículos | B43: 0.05 | C43: =ROUND(B33*(1-B43)/500,0)*500 -> 17000 | D43: ='2-SICOV'!B27 -> 842040 | E43: =IF(C43>0,(C43-D43)/C43,0) -> -48.531765 | F43: =C43-D43 -> -825040 | G43: =IF(E43>=0.6,"✅ Sí","⚠️ Revisar") -> ⚠️ Revisar
A44: 31 – 60 vehículos | B44: 0.08 | C44: =ROUND(B33*(1-B44)/500,0)*500 -> 16500 | D44: ='2-SICOV'!B27 -> 842040 | E44: =IF(C44>0,(C44-D44)/C44,0) -> -50.032727 | F44: =C44-D44 -> -825540 | G44: =IF(E44>=0.6,"✅ Sí","⚠️ Revisar") -> ⚠️ Revisar
A45: 61 – 100 vehículos | B45: 0.12 | C45: =ROUND(B33*(1-B45)/500,0)*500 -> 16000 | D45: ='2-SICOV'!B27 -> 842040 | E45: =IF(C45>0,(C45-D45)/C45,0) -> -51.6275 | F45: =C45-D45 -> -826040 | G45: =IF(E45>=0.6,"✅ Sí","⚠️ Revisar") -> ⚠️ Revisar
...

Sheet 3-App-Conductor
A1: APP CONDUCTOR – GPS Avanzado + Hábitos + Seguridad Vial (PRE-PESV)
A2: ℹ️ Mismo esquema que SICOV: costos técnicos variables + prorrateo operativo. Precio base: COP 28.000/conductor/mes.
A4: A. COSTOS TÉCNICOS VARIABLES POR CONDUCTOR / MES
A5: Concepto | B5: Valor input | C5: Unidad | D5: Costo parcial | G5: Nota
A6: GPS tracking – datos móvil + servidor | B6: 3500 | C6: COP/mes
A7: Procesamiento hábitos conducción (IA) | B7: 1800 | C7: COP/mes
A8: Detección distracciones celular (IA) | B8: 900 | C8: COP/mes
A9: Reconocimiento facial ingreso/salida (IA) | B9: 500 | C9: COP/mes
A10: Alarmas fotomultas / velocidad (API Maps) | B10: 700 | C10: COP/mes
A11: Almacenamiento datos + trayectorias | B11: 400 | C11: COP/mes
A12: Notificaciones push / alertas | B12: 150 | C12: COP/mes
A13: Subtotal costos técnicos / conductor / mes | B13: =SUM(B6:B12) -> 7950
A15: B. PRORRATEO COSTOS OPERATIVOS (desde hoja 1)
A16: Concepto | B16: Valor (COP) | C16: Fuente
A17: Total costos operativos / mes | B17: ='1-Costos-Operativos'!B55 -> 42054500 | C17: ← Hoja 1-Costos-Operativos
A18: Conductores activos | B18: ='1-Costos-Operativos'!B7 -> 50 | C18: ← Hoja 1-Costos-Operativos
A19: PRORRATEO COSTO OPERATIVO / CONDUCTOR / MES | B19: ='1-Costos-Operativos'!B57 -> 841090 | C19: ← Se actualiza automáticamente
A21: C. COSTO TOTAL POR CONDUCTOR / MES
A22: Costos técnicos variables | B22: =B13 -> 7950
A27: Prorrateo costos operativos | B27: ='1-Costos-Operativos'!B57 -> 841090
A32: COSTO TOTAL / CONDUCTOR / MES | B32: =B30+B31 -> 0
A34: D. PRECIO DE MERCADO ACTUAL → MARGEN REAL
A35: Parámetro | B35: Valor | G35: Interpretación
A36: Precio mínimo cobrado hoy (COP/conductor/mes) | B36: 24000 | G36: Conductores con descuento / flota grande
A37: Precio estándar / máximo (COP/conductor/mes) | B37: 28000 | G37: Precio de lista / clientes nuevos
A38: Costo total / conductor / mes | B38: ='3-App-Conductor'!B32 -> 0
A39: MARGEN REAL al precio mínimo | B39: =IF(B36>0,(B36-B38)/B36,0) -> 1
A44: MARGEN REAL al precio estándar (28K) | B44: =IF(B37>0,(B37-B38)/B37,0) -> 1
A54: E. SIMULACIÓN PRECIO Y MARGEN POR VOLUMEN DE CONDUCTORES
A55: Rango conductores | B55: Descuento (%) | C55: Precio / conductor | D55: Costo / conductor | E55: Margen bruto (%) | F55: Utilidad | G55: ¿Viable? (>60%)
A56: 1 – 10 conductores | B56: 0 | C56: =ROUND(B37*(1-B56)/500,0)*500 -> 28000 | D56: ='3-App-Conductor'!B32 -> 0 | E56: =IF(C56>0,(C56-D56)/C56,0) -> 1 | F56: =C56-D56 -> 28000 | G56: =IF(E56>=0.6,"✅ Sí","⚠️ Revisar") -> ✅ Sí
A57: 11 – 30 conductores | B57: 0.05 | C57: =ROUND(B37*(1-B57)/500,0)*500 -> 26500 | D57: ='3-App-Conductor'!B32 -> 0 | E57: =IF(C57>0,(C57-D57)/C57,0) -> 1 | F57: =C57-D57 -> 26500 | G57: =IF(E57>=0.6,"✅ Sí","⚠️ Revisar") -> ✅ Sí
A58: 31 – 60 conductores | B58: 0.08 | C58: =ROUND(B37*(1-B58)/500,0)*500 -> 26000 | D58: ='3-App-Conductor'!B32 -> 0 | E58: =IF(C58>0,(C58-D58)/C58,0) -> 1 | F58: =C58-D58 -> 26000 | G58: =IF(E58>=0.6,"✅ Sí","⚠️ Revisar") -> ✅ Sí
A59: 61 – 100 conductores | B59: 0.12 | C59: =ROUND(B37*(1-B59)/500,0)*500 -> 24500 | D59: ='3-App-Conductor'!B32 -> 0 | E59: =IF(C59>0,(C59-D59)/C59,0) -> 1 | F59: =C59-D59 -> 24500 | G59: =IF(E59>=0.6,"✅ Sí","⚠️ Revisar") -> ✅ Sí
A60: 101 – 200 conductores | B60: 0.16 | C60: =ROUND(B37*(1-B60)/500,0)*500 -> 23500 | D60: ='3-App-Conductor'!B32 -> 0 | E60: =IF(C60>0,(C60-D60)/C60,0) -> 1 | F60: =C60-D60 -> 23500 | G60: =IF(E60>=0.6,"✅ Sí","⚠️ Revisar") -> ✅ Sí
A61: 201+ conductores | B61: 0.2 | C61: =ROUND(B37*(1-B61)/500,0)*500 -> 22500 | D61: ='3-App-Conductor'!B32 -> 0 | E61: =IF(C61>0,(C61-D61)/C61,0) -> 1 | F61: =C61-D61 -> 22500 | G61: =IF(E61>=0.6,"✅ Sí","⚠️ Revisar") -> ✅ Sí

Sheet 4-Alcoholemia-Soplada
A1: MÓDULO ALCOHOLEMIA – Precio por Soplada
A2: ℹ️ Cada soplada genera: 3 fotos faciales (reconocimiento) + 1 foto evidencia + llamada IA. El precio/soplada es variable sobre una base mensual.
A4: A. COSTOS POR SOPLADA (variables técnicos)
A5: Concepto | B5: Valor input | C5: Cant. por soplada | D5: Costo por soplada (COP) | G5: Nota
A6: Fotos reconocimiento facial (por soplada) | B6: 3 | C6: 30 | D6: =B6*C6 -> 90
A7: Foto evidencia del momento (por soplada) | B7: 1 | C7: 30 | D7: =B7*C7 -> 30
A8: Procesamiento IA detección alcohol | B8: 1 | C8: 80 | D8: =B8*C8 -> 80
A9: Transmisión datos IoT (evento) | B9: 1 | C9: 15 | D9: =B9*C9 -> 15
A10: Cómputo servidor por evento | B10: 1 | C10: 25 | D10: =B10*C10 -> 25
A11: Soporte técnico proporcional | B11: 1 | C11: 50 | D11: =B11*C11 -> 50
A12: Contingencia (5% sobre subtotal) | D12: =SUM(D6:D11)*0.05 -> 14.5
A13: COSTO TOTAL POR SOPLADA | D13: =SUM(D6:D11)+D12 -> 304.5
A15: B. PRECIO DE VENTA POR SOPLADA → MARGEN REAL
A16: Parámetro | B16: Valor | G16: Nota
A17: Precio actual cobrado por soplada (COP) | B17: 800 | G17: Precio actual de mercado Protegeme
A18: Costo por soplada (calculado arriba) | B18: ='4-Alcoholemia-Soplada'!D13 -> 304.5
A23: MARGEN REAL por soplada al precio actual | B23: =IF(B17>0,(B17-B22)/B17,0) -> 1
A28: Utilidad por soplada (COP) | B28: =B17-B22 -> 800
A33: Precio sugerido al 70% de margen (COP) | B33: =ROUND(D13/(1-0.7)/10,0)*10 -> 1020 | G33: Si quiere subir a 70% de margen
A35: C. DISPOSITIVO FÍSICO DE ALCOHOLEMIA (venta única)
A36: Concepto | B36: Costo (COP) | G36: Nota
A37: Costo hardware dispositivo | B37: 30000
A38: Logística / envío | B38: 8000
A39: Garantía y reposición (prorrateado) | B39: 5000
A40: COSTO TOTAL DISPOSITIVO | B40: =SUM(B37:B39) -> 43000
A41: Precio de venta dispositivo | B41: 250000 | G41: Precio estándar actual
A42: Margen dispositivo (%) | B42: =IF(B41>0,(B41-B40)/B41,0) -> 0.828

Sheet 5-Alcoholemia-Mensual
A1: MÓDULO ALCOHOLEMIA – Base Mensual por Tamaño de Empresa
A2: ℹ️ La base mensual incluye un paquete de sopladas + almacenamiento de 3 fotos/conductor. Las sopladas extra se cobran por unidad adicional.
A4: A. PARÁMETROS POR TAMAÑO DE EMPRESA
A5: Parámetro | B5: Pequeña | C5: Mediana | D5: Grande | E5: Corporativa | F5: Nota
A6: Vehículos / conductores promedio | B6: 5 | C6: 25 | D6: 100 | E6: 350
A7: Sopladas incluidas / mes | B7: 20 | C7: 100 | D7: 350 | E7: 900
A8: Conductores registrados (fotos) | B8: 5 | C8: 25 | D8: 100 | E8: 350
A9: Precio soplada extra (COP/u) | B9: 800 | C9: 700 | D9: 600 | E9: 500
A11: B. COSTOS MENSUALES POR TAMAÑO
A12: Concepto de Costo | B12: Pequeña | C12: Mediana | D12: Grande | E12: Corporativa | F12: Unidad
A13: Almac. fotos conductores (3 fotos × cond × COP 2/foto/mes) | B13: =3*B8*2 -> 30 | C13: =3*C8*2 -> 150 | D13: =3*D8*2 -> 600 | E13: =3*E8*2 -> 2100 | F13: COP/mes
A14: Almac. fotos evidencia (sopladas × COP 30/foto) | B14: =B7*30 -> 600 | C14: =C7*30 -> 3000 | D14: =D7*30 -> 10500 | E14: =E7*30 -> 27000 | F14: COP/mes
A15: Procesamiento IA (sopladas incluidas × COP 80) | B15: =B7*80 -> 1600 | C15: =C7*80 -> 8000 | D15: =D7*80 -> 28000 | E15: =E7*80 -> 72000 | F15: COP/mes
A16: Infraestructura plataforma fija (por tamaño) | B16: 15000 | C16: 35000 | D16: 80000 | E16: 150000 | F16: COP/mes
A17: Soporte técnico proporcional | B17: 10000 | C17: 25000 | D17: 60000 | E17: 120000 | F17: COP/mes
A18: Contingencia (5%) | B18: =SUM(B13:B17)*0.05 -> 1361.5 | C18: =SUM(C13:C17)*0.05 -> 3557.5 | D18: =SUM(D13:D17)*0.05 -> 8955 | E18: =SUM(E13:E17)*0.05 -> 18555 | F18: COP/mes
A19: COSTO TOTAL MENSUAL | B19: =SUM(B13:B18) -> 28591.5 | C19: =SUM(C13:C18) -> 74707.5 | D19: =SUM(D13:D18) -> 188055 | E19: =SUM(E13:E18) -> 389655
A21: C. PRECIO DE VENTA MENSUAL POR TAMAÑO → MARGEN REAL
A22: Parámetro | B22: Pequeña | C22: Mediana | D22: Grande | E22: Corporativa
A23: Precio mensual cobrado HOY (COP/mes) | B23: 80000 | C23: 200000 | D23: 500000 | E23: 1200000
A24: Costo total mensual (calculado arriba) | B24: ='5-Alcoholemia-Mensual'!B19 -> 28591.5 | C24: ='5-Alcoholemia-Mensual'!C19 -> 74707.5 | D24: ='5-Alcoholemia-Mensual'!D19 -> 188055 | E24: ='5-Alcoholemia-Mensual'!E19 -> 389655
A25: MARGEN REAL al precio actual (%) | B25: =IF(B23>0,(B23-B24)/B23,0) -> 0.64260625 | C25: =IF(C23>0,(C23-C24)/C23,0) -> 0.6264625 | D25: =IF(D23>0,(D23-D24)/D23,0) -> 0.62389 | E25: =IF(E23>0,(E23-E24)/E23,0) -> 0.6752875
A26: Precio sugerido al 70% margen (COP) | B26: =ROUND(B19/(1-0.7)/5000,0)*5000 -> 95000 | C26: =ROUND(C19/(1-0.7)/5000,0)*5000 -> 250000 | D26: =ROUND(D19/(1-0.7)/5000,0)*5000 -> 625000 | E26: =ROUND(E19/(1-0.7)/5000,0)*5000 -> 1300000
A27: Utilidad mensual estimada (COP) | B27: =B23-B24 -> 51408.5 | C27: =C23-C24 -> 125292.5 | D27: =D23-D24 -> 311945 | E27: =E23-E24 -> 810345

Sheet 6-PESV
A1: MÓDULO PESV – Fases 1 y 2 | Supertransporte Colombia
A2: ℹ️ Fase 1: carga histórica + almacenamiento formularios. Fase 2 (FUTURO): integración tiempo real con Supertransporte (precio adicional).
A4: A. CLASIFICACIÓN EMPRESA SUPERTRANSPORTE (criterio PESV)
A5: Categoría | B5: Flota / criterio | C5: Formularios Fase 1 | D5: Almac. archivos est. | F5: Nota
A6: Pequeña | B6: 1–10 vehículos | C6: ~12 formularios | D6: hasta 500 MB | F6: Según clasificación Supertransporte
A7: Mediana | B7: 11–50 vehículos | C7: ~25 formularios | D7: hasta 2 GB | F7: Según clasificación Supertransporte
A8: Grande | B8: 51–200 vehículos | C8: ~40 formularios | D8: hasta 10 GB | F8: Según clasificación Supertransporte
A9: Corporativa | B9: 200+ vehículos | C9: ~60 formularios | D9: hasta 50 GB | F9: Según clasificación Supertransporte
A11: B. COSTOS MENSUALES POR CATEGORÍA – FASE 1 (carga histórica)
A12: Concepto de Costo | B12: Pequeña | C12: Mediana | D12: Grande | E12: Corporativa | F12: Unidad
A13: Almacenamiento archivos (COP/GB/mes) | B13: 500 | C13: 1500 | D13: 6000 | E13: 25000 | F13: COP/mes
A14: Procesamiento IA formularios (extracción) | B14: 8000 | C14: 20000 | D14: 40000 | E14: 80000 | F14: COP/mes
A15: Infraestructura plataforma | B15: 10000 | C15: 25000 | D15: 60000 | E15: 120000 | F15: COP/mes
A16: Soporte implementación (prorrateado/mes) | B16: 5000 | C16: 12000 | D16: 28000 | E16: 55000 | F16: COP/mes
A17: Mantenimiento y actualizaciones | B17: 3000 | C17: 8000 | D17: 20000 | E17: 45000 | F17: COP/mes
A18: Contingencia (5%) | B18: =SUM(B13:B17)*0.05 -> 1325 | C18: =SUM(C13:C17)*0.05 -> 3325 | D18: =SUM(D13:D17)*0.05 -> 7700 | E18: =SUM(E13:E17)*0.05 -> 16250 | F18: COP/mes
A19: COSTO TOTAL MENSUAL FASE 1 | B19: =SUM(B13:B18) -> 27825 | C19: =SUM(C13:C18) -> 69825 | D19: =SUM(D13:D18) -> 161700 | E19: =SUM(E13:E18) -> 341250
A21: C. PRECIO DE VENTA FASE 1 → MARGEN REAL
A22: Parámetro | B22: Pequeña | C22: Mediana | D22: Grande | E22: Corporativa
A23: Precio mensual propuesto (COP/mes) – editar | B23: 80000 | C23: 190000 | D23: 480000 | E23: 1100000
A24: Costo mensual Fase 1 (calculado arriba) | B24: ='6-PESV'!B19 -> 27825 | C24: ='6-PESV'!C19 -> 69825 | D24: ='6-PESV'!D19 -> 161700 | E24: ='6-PESV'!E19 -> 341250
A25: MARGEN REAL Fase 1 (%) | B25: =IF(B23>0,(B23-B24)/B23,0) -> 0.6521875 | C25: =IF(C23>0,(C23-C24)/C23,0) -> 0.6325 | D25: =IF(D23>0,(D23-D24)/D23,0) -> 0.663125 | E25: =IF(E23>0,(E23-E24)/E23,0) -> 0.68977273
A26: Precio sugerido al 70% margen | B26: =ROUND(B19/(1-0.7)/5000,0)*5000 -> 95000 | C26: =ROUND(C19/(1-0.7)/5000,0)*5000 -> 235000 | D26: =ROUND(D19/(1-0.7)/5000,0)*5000 -> 540000 | E26: =ROUND(E19/(1-0.7)/5000,0)*5000 -> 1140000
A28: D. FASE 2 – INTEGRACIÓN TIEMPO REAL CON SUPERTRANSPORTE (FUTURO)
A29: ⏳ Fase 2 disponible cuando esté operativa la integración API con Supertransporte. Precio = Precio Fase 1 × factor adicional.
A30: Parámetro | B30: Pequeña | C30: Mediana | D30: Grande | E30: Corporativa
A31: Factor adicional Fase 2 sobre Fase 1 (%) | B31: 0.4 | C31: 0.4 | D31: 0.4 | E31: 0.4
A32: PRECIO ESTIMADO FASE 2 (COP/mes) | B32: =ROUND(B23*(1+B31)/5000,0)*5000 -> 110000 | C32: =ROUND(C23*(1+C31)/5000,0)*5000 -> 265000 | D32: =ROUND(D23*(1+D31)/5000,0)*5000 -> 670000 | E32: =ROUND(E23*(1+E31)/5000,0)*5000 -> 1540000

Sheet 7-Paquetes
A1: PAQUETES COMERCIALES PROTEGEME – Precios y Descuentos
A2: ℹ️ Simule con los parámetros de la empresa cliente (azul). Las fórmulas calculan el precio lista, el descuento y el precio final del paquete.
A4: A. PARÁMETROS DE SIMULACIÓN (empresa cliente tipo)
A5: Parámetro | B5: Valor | C5: Unidad | H5: Nota
A6: Vehículos del cliente | B6: 20 | C6: vehículos
A7: Conductores del cliente | B7: 20 | C7: conductores
A8: Precio SICOV / veh / mes | B8: 18000 | C8: COP/veh/mes
A9: Precio App Conductor / cond / mes | B9: 28000 | C9: COP/cond/mes
A10: Precio Alc. mensual (empresa mediana) | B10: 200000 | C10: COP/mes
A11: Precio PESV Fase 1 (empresa mediana) | B11: 190000 | C11: COP/mes
A13: B. PAQUETES DISPONIBLES
A14: 📌 Ajuste el % de descuento (azul) según su estrategia. Las celdas verdes muestran el precio final del paquete.
A15: Paquete | B15: Módulos incluidos | C15: Precio Lista (COP/mes) | D15: Descuento (%) | E15: PRECIO PAQUETE | F15: Ahorro (COP) | G15: Margen est. | H15: Estado
A16: Solo SICOV | B16: SICOV | C16: =B8*B6 -> 360000 | D16: 0 | E16: =ROUND(C16*(1-D16)/1000,0)*1000 -> 360000 | F16: =C16-E16 -> 0 | G16: =IF(C16>0,(C16-E16*0.3)/C16,0) -> 0.7 | H16: Alistamiento y mantenimiento vehicular
A17: Solo App Conductor | B17: App Conductor | C17: =B9*B7 -> 560000 | D17: 0 | E17: =ROUND(C17*(1-D17)/1000,0)*1000 -> 560000 | F17: =C17-E17 -> 0 | G17: =IF(C17>0,(C17-E17*0.3)/C17,0) -> 0.7 | H17: GPS + hábitos + seguridad vial
A18: Solo PESV Fase 1 | B18: PESV Fase 1 | C18: =B11 -> 190000 | D18: 0 | E18: =ROUND(C18*(1-D18)/1000,0)*1000 -> 190000 | F18: =C18-E18 -> 0 | G18: =IF(C18>0,(C18-E18*0.3)/C18,0) -> 0.7 | H18: Carga histórica formularios Supertransporte
A19: SICOV + PESV | B19: SICOV + PESV F1 | C19: =B8*B6+B11 -> 550000 | D19: 0.1 | E19: =ROUND(C19*(1-D19)/1000,0)*1000 -> 495000 | F19: =C19-E19 -> 55000 | G19: =IF(C19>0,(C19-E19*0.3)/C19,0) -> 0.73 | H19: Compliance básico ✅
A20: App Conductor + Alcoholemia mensual | B20: App + Alcoholemia | C20: =B9*B7+B10 -> 760000 | D20: 0.08 | E20: =ROUND(C20*(1-D20)/1000,0)*1000 -> 699000 | F20: =C20-E20 -> 61000 | G20: =IF(C20>0,(C20-E20*0.3)/C20,0) -> 0.72407895 | H20: Control conductor + alcohol
A21: SICOV + App Conductor + PESV | B21: SICOV + App + PESV | C21: =B8*B6+B9*B7+B11 -> 1110000 | D21: 0.15 | E21: =ROUND(C21*(1-D21)/1000,0)*1000 -> 944000 | F21: =C21-E21 -> 166000 | G21: =IF(C21>0,(C21-E21*0.3)/C21,0) -> 0.74486486 | H21: Paquete PRE-PESV completo ✅
A22: SICOV + App + Alcoholemia + PESV | B22: SICOV + App + Alc + PESV | C22: =B8*B6+B9*B7+B10+B11 -> 1310000 | D22: 0.2 | E22: =ROUND(C22*(1-D22)/1000,0)*1000 -> 1048000 | F22: =C22-E22 -> 262000 | G22: =IF(C22>0,(C22-E22*0.3)/C22,0) -> 0.76 | H22: Paquete FULL – máxima cobertura ✅
A23: SICOV + Alcoholemia mensual | B23: SICOV + Alcoholemia | C23: =B8*B6+B10 -> 560000 | D23: 0.08 | E23: =ROUND(C23*(1-D23)/1000,0)*1000 -> 515000 | F23: =C23-E23 -> 45000 | G23: =IF(C23>0,(C23-E23*0.3)/C23,0) -> 0.72410714 | H23: Flota + control alcohol
A24: PESV Fase 2 – tiempo real (FUTURO) | B24: PESV F2 (integración API) | C24: =B11*1.4 -> 266000 | D24: 0 | E24: =ROUND(C24*(1-D24)/1000,0)*1000 -> 266000 | F24: =C24-E24 -> 0 | G24: =IF(C24>0,(C24-E24*0.3)/C24,0) -> 0.7 | H24: ⏳ Disponible cuando esté lista la API Supertransporte
A25: ⚠️ El margen de la col G es estimado (asume ~30% de costo sobre precio lista). Para el margen exacto consulte las hojas de cada módulo.

Sheet 8-Resumen
A1: RESUMEN EJECUTIVO – Protegeme Pricing Model | ITFusion 2026
A2: ℹ️ Vista consolidada para inversionistas y equipo comercial. Modifique los datos en las hojas fuente; este resumen se actualiza automáticamente.
A4: A. COSTOS OPERATIVOS TOTALES / MES
A5: Concepto | B5: COP / mes | C5: Proyección 6M
A6: Total costos operativos / mes | B6: ='1-Costos-Operativos'!B55 -> 42054500 | C6: Ver hoja 1 col. Proyección
A10: Vehículos activos (SICOV) | B10: ='1-Costos-Operativos'!B6 -> 50
A15: Conductores activos (App Conductor) | B15: ='1-Costos-Operativos'!B7 -> 50
A25: B. PRECIOS DE VENTA Y MÁRGENES REALES HOY
A26: Módulo / Servicio | B26: Precio de venta (COP) | C26: Unidad | D26: Costo estimado | E26: Margen real (%) | G26: Estado
A27: SICOV – precio mínimo | B27: ='2-SICOV'!B32 -> 14000 | C27: COP/veh/mes | D27: ='2-SICOV'!B27 -> 842040 | E27: =IF(B27>0,(B27-D27)/B27,0) -> -59.145714 | G27: ✅ Activo
A28: SICOV – precio estándar | B28: ='2-SICOV'!B33 -> 18000 | C28: COP/veh/mes | D28: ='2-SICOV'!B27 -> 842040 | E28: =IF(B28>0,(B28-D28)/B28,0) -> -45.78 | G28: ✅ Activo
A29: App Conductor – mínimo | B29: ='3-App-Conductor'!B36 -> 24000 | C29: COP/cond/mes | D29: ='3-App-Conductor'!B32 -> 0 | E29: =IF(B29>0,(B29-D29)/B29,0) -> 1 | G29: ✅ Activo
A30: App Conductor – estándar | B30: ='3-App-Conductor'!B37 -> 28000 | C30: COP/cond/mes | D30: ='3-App-Conductor'!B32 -> 0 | E30: =IF(B30>0,(B30-D30)/B30,0) -> 1 | G30: ✅ Activo
A31: Alcoholemia – por soplada | B31: ='4-Alcoholemia-Soplada'!B17 -> 800 | C31: COP/soplada | D31: ='4-Alcoholemia-Soplada'!D13 -> 304.5 | E31: =IF(B31>0,(B31-D31)/B31,0) -> 0.619375 | G31: ✅ Activo
A32: Dispositivo alcoholemia | B32: ='4-Alcoholemia-Soplada'!B41 -> 250000 | C32: COP unidad | D32: ='4-Alcoholemia-Soplada'!B40 -> 43000 | E32: =IF(B32>0,(B32-D32)/B32,0) -> 0.828 | G32: ✅ Activo
A33: PESV Fase 1 – Mediana | B33: ='6-PESV'!C23 -> 190000 | C33: COP/mes empresa | D33: ='6-PESV'!C19 -> 69825 | E33: =IF(B33>0,(B33-D33)/B33,0) -> 0.6325 | G33: ✅ Activo
A34: PESV Fase 1 – Grande | B34: ='6-PESV'!D23 -> 480000 | C34: COP/mes empresa | D34: ='6-PESV'!D19 -> 161700 | E34: =IF(B34>0,(B34-D34)/B34,0) -> 0.663125 | G34: ✅ Activo
A36: C. PAQUETES DESTACADOS (empresa referencia 20 veh / 20 conductores)
A37: Paquete | B37: Precio lista (COP/mes) | C37: Descuento | D37: Precio paquete | E37: Ahorro cliente | G37: Recomendado
A38: Solo SICOV | B38: ='7-Paquetes'!C16 -> 360000 | C38: ='7-Paquetes'!D16 -> 0 | D38: ='7-Paquetes'!E16 -> 360000 | E38: ='7-Paquetes'!F16 -> 0
A39: SICOV + PESV | B39: ='7-Paquetes'!C19 -> 550000 | C39: ='7-Paquetes'!D19 -> 0.1 | D39: ='7-Paquetes'!E19 -> 495000 | E39: ='7-Paquetes'!F19 -> 55000 | G39: Compliance básico
A40: SICOV + App + PESV | B40: ='7-Paquetes'!C21 -> 1110000 | C40: ='7-Paquetes'!D21 -> 0.15 | D40: ='7-Paquetes'!E21 -> 944000 | E40: ='7-Paquetes'!F21 -> 166000 | G40: PRE-PESV completo ✅
A41: SICOV + App + Alc + PESV | B41: ='7-Paquetes'!C22 -> 1310000 | C41: ='7-Paquetes'!D22 -> 0.2 | D41: ='7-Paquetes'!E22 -> 1048000 | E41: ='7-Paquetes'!F22 -> 262000 | G41: Paquete FULL ✅
A42: PESV Fase 2 (FUTURO) | B42: ='7-Paquetes'!C24 -> 266000 | C42: ='7-Paquetes'!D24 -> 0 | D42: ='7-Paquetes'!E24 -> 266000 | E42: ='7-Paquetes'!F24 -> 0 | G42: ⏳ Próximamente
A44: 📌 Para ajustar cualquier precio o supuesto, vaya a la hoja correspondiente y modifique las celdas en AZUL. Este resumen se actualiza automáticamente.
A45: 💡 CLAVE: a medida que crece el número de clientes (hoja 1-Costos-Operativos, celdas B6 y B7), el costo por vehículo/conductor baja y el margen real sube.

Sheet 9-Alc-Planes-Volumen
A1: ALCOHOLEMIA – Planes de Precios y Tabla de Volumen de Sopladas
A2: ℹ️ Azul = editable. 3 planes disponibles: Pay-per-use | Plan Fijo Mensual | Plan Prepago con descuento. La tabla de volumen muestra el precio por soplada y total mensual según consumo.
A4: A. COSTO BASE POR SOPLADA (vinculado automáticamente de hoja 4-Alcoholemia-Soplada)
A5: Concepto | B5: COP
A6: Costo total por soplada (técnico) | B6: ='4-Alcoholemia-Soplada'!D13 -> 304.5 | C6: ← Desde hoja 4 (se actualiza solo)
A7: Precio actual pay-per-use (COP/soplada) | B7: ='4-Alcoholemia-Soplada'!B17 -> 800
A9: B. PARÁMETROS DE LOS 3 PLANES (celdas azules = editar)
A10: Parámetro / Plan | B10: PLAN 1: Pay-per-Use | E10: PLAN 2: Fijo Mensual | H10: PLAN 3: Prepago (desc.)
B11: Precio/soplada (COP) | C11: Margen obj. (%) | D11: Nota | E11: Sopladas incluidas | F11: Precio fijo/mes (COP) | G11: Extra/soplada (COP) | H11: Sopladas incluidas | I11: Precio prepago/mes | J11: Desc. vs Plan 1 (%)
A12: Básico (hasta 300 sopladas) | B12: 800 | C12: 0.7 | D12: Estándar | E12: 300 | F12: =ROUND(B6*E12/(1-C12)/5000,0)*5000 -> 305000 | G12: 900 | H12: 300 | I12: =ROUND(F12*0.92/5000,0)*5000 -> 280000 | J12: =IF(F12>0,(F12-I12)/F12,0) -> 0.081967213
A13: Estándar (hasta 900 sopladas) | B13: 750 | C13: 0.7 | D13: Volumen M | E13: 900 | F13: =ROUND(B6*E13/(1-C13)/5000,0)*5000 -> 915000 | G13: 800 | H13: 900 | I13: =ROUND(F13*0.92/5000,0)*5000 -> 840000 | J13: =IF(F13>0,(F13-I13)/F13,0) -> 0.081967213
A14: Avanzado (hasta 2000 sopladas) | B14: 680 | C14: 0.68 | D14: Volumen G | E14: 2000 | F14: =ROUND(B6*E14/(1-C14)/5000,0)*5000 -> 1905000 | G14: 720 | H14: 2000 | I14: =ROUND(F14*0.92/5000,0)*5000 -> 1755000 | J14: =IF(F14>0,(F14-I14)/F14,0) -> 0.078740157
A15: Pro (hasta 5000 sopladas) | B15: 600 | C15: 0.67 | D15: Corp. | E15: 5000 | F15: =ROUND(B6*E15/(1-C15)/5000,0)*5000 -> 4615000 | G15: 640 | H15: 5000 | I15: =ROUND(F15*0.92/5000,0)*5000 -> 4245000 | J15: =IF(F15>0,(F15-I15)/F15,0) -> 0.080173348
A16: Ultra (5000+ sopladas) | B16: 520 | C16: 0.65 | D16: Masivo | E16: 8000 | F16: =ROUND(B6*E16/(1-C16)/5000,0)*5000 -> 6960000 | G16: 560 | H16: 8000 | I16: =ROUND(F16*0.92/5000,0)*5000 -> 6405000 | J16: =IF(F16>0,(F16-I16)/F16,0) -> 0.079741379
A17: 📌 Plan 2 precio fijo = costo de sopladas incluidas / (1-margen). Plan 3 prepago = Plan 2 × 92% (8% descuento por pago anticipado). Ajuste los % a su criterio.
A19: C. TABLA DE VOLUMEN – PRECIO POR SOPLADA Y COSTO MENSUAL SEGÚN CONSUMO
A20: 📌 4 rangos de consumo. La columna amarilla (Consumo ref.) es editable — cámbiela para ver el precio de cualquier volumen. Los 3 planes side-by-side para comparar.
A21: Rango de Sopladas / mes | B21: Consumo ref. | C21: PLAN 1: Pay-per-Use | F21: PLAN 2: Fijo Mensual | I21: PLAN 3: Prepago
B22: Sopladas | C22: Precio/soplada | D22: Total mes (COP) | E22: Margen (%) | F22: Plan aplicable | G22: Total mes fijo (COP) | H22: Ahorro vs P1 (COP) | I22: Total prepago (COP) | J22: Ahorro vs P1 (%)
A23: 0 – 300 | B23: 150 | C23: =B12 -> 800 | D23: =B23*C23 -> 120000 | E23: =IF(C23>0,(C23-B6)/C23,0) -> 0.619375 | F23: Básico | G23: =F12 -> 305000 | H23: =MAX(0,D23-G23) -> 0 | I23: =I12 -> 280000 | J23: =IF(D23>0,(D23-I23)/D23,0) -> -1.3333333
A24: 301 – 900 | B24: 600 | C24: =B13 -> 750 | D24: =B24*C24 -> 450000 | E24: =IF(C24>0,(C24-B6)/C24,0) -> 0.594 | F24: Estándar | G24: =F13 -> 915000 | H24: =MAX(0,D24-G24) -> 0 | I24: =I13 -> 840000 | J24: =IF(D24>0,(D24-I24)/D24,0) -> -0.86666667
A25: 901 – 2.000 | B25: 1500 | C25: =B14 -> 680 | D25: =B25*C25 -> 1020000 | E25: =IF(C25>0,(C25-B6)/C25,0) -> 0.55220588 | F25: Avanzado | G25: =F14 -> 1905000 | H25: =MAX(0,D25-G25) -> 0 | I25: =I14 -> 1755000 | J25: =IF(D25>0,(D25-I25)/D25,0) -> -0.72058824
A26: 2.001 – 4.000 | B26: 3000 | C26: =B15 -> 600 | D26: =B26*C26 -> 1800000 | E26: =IF(C26>0,(C26-B6)/C26,0) -> 0.4925 | F26: Pro | G26: =F15 -> 4615000 | H26: =MAX(0,D26-G26) -> 0 | I26: =I15 -> 4245000 | J26: =IF(D26>0,(D26-I26)/D26,0) -> -1.3583333
A27: 💡 Columna B (amarilla) = sopladas de referencia. Cámbiela para simular cualquier consumo. El precio/soplada y el total mensual se recalculan solos.
A28: ⚠️ Si el consumo supera el tope del Plan Fijo/Prepago, las sopladas extra se cobran al precio de col G (sección B). Plan Corporativo: sin tope de sopladas.

Sheet 10-Cotizador
A1: COTIZADOR INTERACTIVO – Protegeme | Configure y calcule su propuesta
A2: ℹ️ Instrucciones: (1) Ingrese los datos del cliente en AZUL. (2) Active los módulos con 1=Sí / 0=No. (3) Seleccione el plan de alcoholemia. (4) El resumen y precio final se calculan automáticamente.
A4: A. DATOS DEL CLIENTE
A5: Campo | B5: Valor
A6: Nombre empresa / cliente | B6: Empresa XYZ S.A.S.
A7: NIT | B7: 900.000.000-0
A8: Sector transporte | B8: Carga / Pasajeros / Especial
A9: Ciudad | B9: Bogotá
A10: Contacto comercial | B10: Madeleine Andrade
A11: Fecha cotización | B11: 31/03/2026
A12: Vigencia oferta (días) | B12: 30
A14: B. MÓDULOS A CONTRATAR (1 = Incluir / 0 = No incluir)
A15: Módulo / Servicio | B15: ¿Incluir? (1/0) | C15: Cantidad | D15: Unidad | E15: Precio unitario (COP) | F15: Descuento (%) | G15: Subtotal/mes (COP)
A16: SICOV – Alistamiento vehicular | B16: 1 | C16: 20 | D16: vehículos | E16: 18000 | F16: 0 | G16: =B16*C16*E16*(1-F16) -> 360000
A17: App Conductor – GPS + Hábitos + Seg. Vial | B17: 1 | C17: 20 | D17: conductores | E17: 28000 | F17: 0 | G17: =B17*C17*E17*(1-F17) -> 560000
A18: Alcoholemia – Plan Pay-per-Use | B18: 0 | C18: 0 | D18: sopladas/mes | E18: 800 | F18: 0 | G18: =B18*C18*E18*(1-F18) -> 0
A19: Alcoholemia – Plan Fijo Mensual | B19: 1 | C19: 1 | D19: empresa | E19: 200000 | F19: 0 | G19: =B19*C19*E19*(1-F19) -> 200000
A20: Alcoholemia – Plan Prepago (desc. 8%) | B20: 0 | C20: 1 | D20: empresa | E20: 0 | F20: 0.08 | G20: =B20*C20*E20*(1-F20) -> 0
A21: PESV Fase 1 – carga histórica formularios | B21: 1 | C21: 1 | D21: empresa | E21: 190000 | F21: 0 | G21: =B21*C21*E21*(1-F21) -> 190000
A22: PESV Fase 2 – tiempo real Supertransporte | B22: 0 | C22: 1 | D22: empresa | E22: 0 | F22: 0 | G22: =B22*C22*E22*(1-F22) -> 0
A23: ⚠️ PESV Fase 2: ingrese el precio en E cuando esté disponible la integración API Supertransporte. Active con 1 cuando esté listo.
A25: C. ALCOHOLEMIA – DETALLE PLAN SELECCIONADO (solo si Plan Fijo o Prepago activo)
A26: 📌 Configure el consumo esperado de sopladas para ver si el plan fijo conviene vs pay-per-use.
A27: Concepto | B27: Valor
A28: Sopladas estimadas / mes | B28: 600
A29: Precio pay-per-use equivalente (COP/soplada) | B29: ='9-Alc-Planes-Volumen'!B7 -> 800
A30: Costo estimado Pay-per-Use (COP/mes) | B30: =B28*B29 -> 480000
A31: Precio Plan Fijo Mensual aplicable (COP/mes) | B31: ='9-Alc-Planes-Volumen'!G23 -> 305000
A32: Precio Plan Prepago aplicable (COP/mes) | B32: ='9-Alc-Planes-Volumen'!I23 -> 280000
A33: AHORRO vs Pay-per-Use – Plan Fijo (COP) | B33: =MAX(0,B30-B31) -> 175000
A34: AHORRO vs Pay-per-Use – Plan Prepago (COP) | B34: =MAX(0,B30-B32) -> 200000
A35: ✅ Plan más conveniente para este consumo | B35: =IF(AND(B33=0,B34=0),"✅ Pay-per-Use (volumen bajo)",IF(B34>=B33,"✅ Plan Prepago (mayor ahorro)","✅ Plan Fijo Mensual")) -> ✅ Plan Prepago (mayor ahorro)
A37: D. DESCUENTO GLOBAL POR PAQUETE
A38: Parámetro | B38: Valor | C38: Criterio
A39: Módulos activos contratados | B39: =SUMIF(B16:B22,1,B16:B22) -> 4 | C39: Cuenta automáticamente los módulos con 1
A40: Descuento global por paquete (%) | B40: 0.1 | C40: Ajuste según cantidad de módulos contratados
A41: 💡 Sugerencia: 1 módulo = 0%, 2 módulos = 5%, 3 módulos = 10%, 4+ módulos = 15–20%.
A43: E. RESUMEN DE COTIZACIÓN
A44: CONCEPTO | E44: VALOR (COP/mes)
A45: Subtotal precio lista (sin descuento) | E45: =SUMPRODUCT((B16:B22)*C16:C22*E16:E22) -> 1310000
...
